DEBUG:asyncio:Using proactor: IocpProactor
DEBUG:asyncio:Using proactor: IocpProactor
WARNING:django.request:Not Found: /register/
WARNING:django.request:Not Found: /register/
WARNING:django.request:Not Found: /register/
INFO:django.utils.autoreload:D:\Web app\babaco\babaco\urls.py changed, reloading.
DEBUG:asyncio:Using proactor: IocpProactor
WARNING:django.request:Not Found: /
WARNING:django.request:Not Found: /
INFO:django.utils.autoreload:D:\Web app\babaco\babaco\urls.py changed, reloading.
DEBUG:asyncio:Using proactor: IocpProactor
WARNING:django.request:Not Found: /register/
INFO:django.utils.autoreload:D:\Web app\babaco\shop\urls.py changed, reloading.
DEBUG:asyncio:Using proactor: IocpProactor
INFO:django.utils.autoreload:D:\Web app\babaco\user\urls.py changed, reloading.
DEBUG:asyncio:Using proactor: IocpProactor
ERROR:django.request:Internal Server Error: /register/
Traceback (most recent call last):
  File "D:\Web app\django\lib\site-packages\django\template\backends\django.py", line 61, in render
    return self.template.render(context)
  File "D:\Web app\django\lib\site-packages\django\template\base.py", line 170, in render
    return self._render(context)
  File "D:\Web app\django\lib\site-packages\django\template\base.py", line 162, in _render
    return self.nodelist.render(context)
  File "D:\Web app\django\lib\site-packages\django\template\base.py", line 938, in render
    bit = node.render_annotated(context)
  File "D:\Web app\django\lib\site-packages\django\template\base.py", line 905, in render_annotated
    return self.render(context)
  File "D:\Web app\django\lib\site-packages\django\template\loader_tags.py", line 127, in render
    compiled_parent = self.get_parent(context)
  File "D:\Web app\django\lib\site-packages\django\template\loader_tags.py", line 124, in get_parent
    return self.find_template(parent, context)
  File "D:\Web app\django\lib\site-packages\django\template\loader_tags.py", line 103, in find_template
    template, origin = context.template.engine.find_template(
  File "D:\Web app\django\lib\site-packages\django\template\engine.py", line 129, in find_template
    raise TemplateDoesNotExist(name, tried=tried)
django.template.exceptions.TemplateDoesNotExist: store/base.html

The above exception was the direct cause of the following exception:

Traceback (most recent call last):
  File "D:\Web app\django\lib\site-packages\django\core\handlers\exception.py", line 47, in inner
    response = get_response(request)
  File "D:\Web app\django\lib\site-packages\django\core\handlers\base.py", line 179, in _get_response
    response = wrapped_callback(request, *callback_args, **callback_kwargs)
  File "D:\Web app\babaco\user\views.py", line 13, in customer_registration_view
    return registration_view(req, usr='user', reg_form=CustomerRegistrationForm)
  File "D:\Web app\babaco\shop\views.py", line 33, in registration_view
    return render(req, 'shop/registration.html', {'form': form, 'title': 'register', 'usr': usr})
  File "D:\Web app\django\lib\site-packages\django\shortcuts.py", line 19, in render
    content = loader.render_to_string(template_name, context, request, using=using)
  File "D:\Web app\django\lib\site-packages\django\template\loader.py", line 62, in render_to_string
    return template.render(context, request)
  File "D:\Web app\django\lib\site-packages\django\template\backends\django.py", line 63, in render
    reraise(exc, self.backend)
  File "D:\Web app\django\lib\site-packages\django\template\backends\django.py", line 84, in reraise
    raise new from exc
django.template.exceptions.TemplateDoesNotExist: store/base.html
ERROR:django.request:Internal Server Error: /register/
Traceback (most recent call last):
  File "D:\Web app\django\lib\site-packages\django\core\handlers\exception.py", line 47, in inner
    response = get_response(request)
  File "D:\Web app\django\lib\site-packages\django\core\handlers\base.py", line 179, in _get_response
    response = wrapped_callback(request, *callback_args, **callback_kwargs)
  File "D:\Web app\babaco\user\views.py", line 13, in customer_registration_view
    return registration_view(req, usr='user', reg_form=CustomerRegistrationForm)
  File "D:\Web app\babaco\shop\views.py", line 20, in registration_view
    return redirect(usr + 'home')
  File "D:\Web app\django\lib\site-packages\django\shortcuts.py", line 41, in redirect
    return redirect_class(resolve_url(to, *args, **kwargs))
  File "D:\Web app\django\lib\site-packages\django\shortcuts.py", line 131, in resolve_url
    return reverse(to, args=args, kwargs=kwargs)
  File "D:\Web app\django\lib\site-packages\django\urls\base.py", line 87, in reverse
    return iri_to_uri(resolver._reverse_with_prefix(view, prefix, *args, **kwargs))
  File "D:\Web app\django\lib\site-packages\django\urls\resolvers.py", line 685, in _reverse_with_prefix
    raise NoReverseMatch(msg)
django.urls.exceptions.NoReverseMatch: Reverse for 'userhome' not found. 'userhome' is not a valid view function or pattern name.
INFO:django.utils.autoreload:D:\Web app\babaco\shop\views.py changed, reloading.
DEBUG:asyncio:Using proactor: IocpProactor
ERROR:django.request:Internal Server Error: /register/
Traceback (most recent call last):
  File "D:\Web app\django\lib\site-packages\django\urls\base.py", line 72, in reverse
    extra, resolver = resolver.namespace_dict[ns]
KeyError: 'user'

During handling of the above exception, another exception occurred:

Traceback (most recent call last):
  File "D:\Web app\django\lib\site-packages\django\core\handlers\exception.py", line 47, in inner
    response = get_response(request)
  File "D:\Web app\django\lib\site-packages\django\core\handlers\base.py", line 179, in _get_response
    response = wrapped_callback(request, *callback_args, **callback_kwargs)
  File "D:\Web app\babaco\user\views.py", line 13, in customer_registration_view
    return registration_view(req, usr='user', reg_form=CustomerRegistrationForm)
  File "D:\Web app\babaco\shop\views.py", line 20, in registration_view
    return redirect(usr + ':home')
  File "D:\Web app\django\lib\site-packages\django\shortcuts.py", line 41, in redirect
    return redirect_class(resolve_url(to, *args, **kwargs))
  File "D:\Web app\django\lib\site-packages\django\shortcuts.py", line 131, in resolve_url
    return reverse(to, args=args, kwargs=kwargs)
  File "D:\Web app\django\lib\site-packages\django\urls\base.py", line 83, in reverse
    raise NoReverseMatch("%s is not a registered namespace" % key)
django.urls.exceptions.NoReverseMatch: 'user' is not a registered namespace
INFO:django.utils.autoreload:D:\Web app\babaco\babaco\urls.py changed, reloading.
DEBUG:asyncio:Using proactor: IocpProactor
INFO:django.utils.autoreload:D:\Web app\babaco\shop\urls.py changed, reloading.
DEBUG:asyncio:Using proactor: IocpProactor
INFO:django.utils.autoreload:D:\Web app\babaco\shop\urls.py changed, reloading.
DEBUG:asyncio:Using proactor: IocpProactor
INFO:django.utils.autoreload:D:\Web app\babaco\shop\urls.py changed, reloading.
DEBUG:asyncio:Using proactor: IocpProactor
ERROR:django.request:Internal Server Error: /register/
Traceback (most recent call last):
  File "D:\Web app\django\lib\site-packages\django\urls\base.py", line 72, in reverse
    extra, resolver = resolver.namespace_dict[ns]
KeyError: 'user'

During handling of the above exception, another exception occurred:

Traceback (most recent call last):
  File "D:\Web app\django\lib\site-packages\django\core\handlers\exception.py", line 47, in inner
    response = get_response(request)
  File "D:\Web app\django\lib\site-packages\django\core\handlers\base.py", line 179, in _get_response
    response = wrapped_callback(request, *callback_args, **callback_kwargs)
  File "D:\Web app\babaco\user\views.py", line 13, in customer_registration_view
    return registration_view(req, usr='user', reg_form=CustomerRegistrationForm)
  File "D:\Web app\babaco\shop\views.py", line 20, in registration_view
    return redirect(usr + ':home')
  File "D:\Web app\django\lib\site-packages\django\shortcuts.py", line 41, in redirect
    return redirect_class(resolve_url(to, *args, **kwargs))
  File "D:\Web app\django\lib\site-packages\django\shortcuts.py", line 131, in resolve_url
    return reverse(to, args=args, kwargs=kwargs)
  File "D:\Web app\django\lib\site-packages\django\urls\base.py", line 83, in reverse
    raise NoReverseMatch("%s is not a registered namespace" % key)
django.urls.exceptions.NoReverseMatch: 'user' is not a registered namespace
DEBUG:asyncio:Using proactor: IocpProactor
ERROR:django.request:Internal Server Error: /register/
Traceback (most recent call last):
  File "D:\Web app\django\lib\site-packages\django\urls\base.py", line 72, in reverse
    extra, resolver = resolver.namespace_dict[ns]
KeyError: 'user'

During handling of the above exception, another exception occurred:

Traceback (most recent call last):
  File "D:\Web app\django\lib\site-packages\django\core\handlers\exception.py", line 47, in inner
    response = get_response(request)
  File "D:\Web app\django\lib\site-packages\django\core\handlers\base.py", line 179, in _get_response
    response = wrapped_callback(request, *callback_args, **callback_kwargs)
  File "D:\Web app\babaco\user\views.py", line 13, in customer_registration_view
    return registration_view(req, usr='user', reg_form=CustomerRegistrationForm)
  File "D:\Web app\babaco\shop\views.py", line 20, in registration_view
    return redirect(usr + ':home')
  File "D:\Web app\django\lib\site-packages\django\shortcuts.py", line 41, in redirect
    return redirect_class(resolve_url(to, *args, **kwargs))
  File "D:\Web app\django\lib\site-packages\django\shortcuts.py", line 131, in resolve_url
    return reverse(to, args=args, kwargs=kwargs)
  File "D:\Web app\django\lib\site-packages\django\urls\base.py", line 83, in reverse
    raise NoReverseMatch("%s is not a registered namespace" % key)
django.urls.exceptions.NoReverseMatch: 'user' is not a registered namespace
INFO:django.utils.autoreload:D:\Web app\babaco\shop\views.py changed, reloading.
DEBUG:asyncio:Using proactor: IocpProactor
ERROR:django.request:Internal Server Error: /register/
Traceback (most recent call last):
  File "D:\Web app\django\lib\site-packages\django\core\handlers\exception.py", line 47, in inner
    response = get_response(request)
  File "D:\Web app\django\lib\site-packages\django\core\handlers\base.py", line 179, in _get_response
    response = wrapped_callback(request, *callback_args, **callback_kwargs)
  File "D:\Web app\babaco\user\views.py", line 13, in customer_registration_view
    return registration_view(req, usr='user', reg_form=CustomerRegistrationForm)
  File "D:\Web app\babaco\shop\views.py", line 20, in registration_view
    return redirect('home')
  File "D:\Web app\django\lib\site-packages\django\shortcuts.py", line 41, in redirect
    return redirect_class(resolve_url(to, *args, **kwargs))
  File "D:\Web app\django\lib\site-packages\django\shortcuts.py", line 131, in resolve_url
    return reverse(to, args=args, kwargs=kwargs)
  File "D:\Web app\django\lib\site-packages\django\urls\base.py", line 87, in reverse
    return iri_to_uri(resolver._reverse_with_prefix(view, prefix, *args, **kwargs))
  File "D:\Web app\django\lib\site-packages\django\urls\resolvers.py", line 685, in _reverse_with_prefix
    raise NoReverseMatch(msg)
django.urls.exceptions.NoReverseMatch: Reverse for 'home' not found. 'home' is not a valid view function or pattern name.
INFO:django.utils.autoreload:D:\Web app\babaco\shop\views.py changed, reloading.
DEBUG:asyncio:Using proactor: IocpProactor
INFO:django.utils.autoreload:D:\Web app\babaco\shop\urls.py changed, reloading.
DEBUG:asyncio:Using proactor: IocpProactor
INFO:django.utils.autoreload:D:\Web app\babaco\user\urls.py changed, reloading.
DEBUG:asyncio:Using proactor: IocpProactor
DEBUG:asyncio:Using proactor: IocpProactor
INFO:django.utils.autoreload:D:\Web app\babaco\user\forms.py changed, reloading.
DEBUG:asyncio:Using proactor: IocpProactor
INFO:django.utils.autoreload:D:\Web app\babaco\user\views.py changed, reloading.
DEBUG:asyncio:Using proactor: IocpProactor
INFO:django.utils.autoreload:D:\Web app\babaco\shop\views.py changed, reloading.
DEBUG:asyncio:Using proactor: IocpProactor
INFO:django.utils.autoreload:D:\Web app\babaco\shop\views.py changed, reloading.
DEBUG:asyncio:Using proactor: IocpProactor
INFO:django.utils.autoreload:D:\Web app\babaco\shop\views.py changed, reloading.
DEBUG:asyncio:Using proactor: IocpProactor
INFO:django.utils.autoreload:D:\Web app\babaco\shop\views.py changed, reloading.
DEBUG:asyncio:Using proactor: IocpProactor
INFO:django.utils.autoreload:D:\Web app\babaco\user\views.py changed, reloading.
DEBUG:asyncio:Using proactor: IocpProactor
INFO:django.utils.autoreload:D:\Web app\babaco\user\urls.py changed, reloading.
DEBUG:asyncio:Using proactor: IocpProactor
ERROR:django.request:Internal Server Error: /login/
Traceback (most recent call last):
  File "D:\Web app\django\lib\site-packages\django\core\handlers\exception.py", line 47, in inner
    response = get_response(request)
  File "D:\Web app\django\lib\site-packages\django\core\handlers\base.py", line 179, in _get_response
    response = wrapped_callback(request, *callback_args, **callback_kwargs)
TypeError: login_view() missing 2 required positional arguments: 'usr' and 'database'
DEBUG:asyncio:Using proactor: IocpProactor
ERROR:django.request:Internal Server Error: /login/
Traceback (most recent call last):
  File "D:\Web app\django\lib\site-packages\django\core\handlers\exception.py", line 47, in inner
    response = get_response(request)
  File "D:\Web app\django\lib\site-packages\django\core\handlers\base.py", line 179, in _get_response
    response = wrapped_callback(request, *callback_args, **callback_kwargs)
TypeError: login_view() missing 2 required positional arguments: 'usr' and 'database'
INFO:django.utils.autoreload:D:\Web app\babaco\user\views.py changed, reloading.
DEBUG:asyncio:Using proactor: IocpProactor
ERROR:django.request:Internal Server Error: /login/
Traceback (most recent call last):
  File "D:\Web app\django\lib\site-packages\django\core\handlers\exception.py", line 47, in inner
    response = get_response(request)
  File "D:\Web app\django\lib\site-packages\django\core\handlers\base.py", line 179, in _get_response
    response = wrapped_callback(request, *callback_args, **callback_kwargs)
TypeError: login_view() missing 2 required positional arguments: 'usr' and 'database'
INFO:django.utils.autoreload:D:\Web app\babaco\user\views.py changed, reloading.
DEBUG:asyncio:Using proactor: IocpProactor
ERROR:django.request:Internal Server Error: /login/
Traceback (most recent call last):
  File "D:\Web app\django\lib\site-packages\django\core\handlers\exception.py", line 47, in inner
    response = get_response(request)
  File "D:\Web app\django\lib\site-packages\django\core\handlers\base.py", line 179, in _get_response
    response = wrapped_callback(request, *callback_args, **callback_kwargs)
TypeError: login_view() missing 2 required positional arguments: 'usr' and 'database'
INFO:django.utils.autoreload:D:\Web app\babaco\user\urls.py changed, reloading.
DEBUG:asyncio:Using proactor: IocpProactor
DEBUG:asyncio:Using proactor: IocpProactor
INFO:django.utils.autoreload:D:\Web app\babaco\user\views.py changed, reloading.
DEBUG:asyncio:Using proactor: IocpProactor
INFO:django.utils.autoreload:D:\Web app\babaco\shop\views.py changed, reloading.
DEBUG:asyncio:Using proactor: IocpProactor
WARNING:django.request:Not Found: /favicon.ico
WARNING:django.request:Not Found: /ogin
INFO:django.utils.autoreload:D:\Web app\babaco\shop\views.py changed, reloading.
DEBUG:asyncio:Using proactor: IocpProactor
WARNING:django.request:Not Found: /favicon.ico
INFO:django.utils.autoreload:D:\Web app\babaco\store\urls.py changed, reloading.
DEBUG:asyncio:Using proactor: IocpProactor
INFO:django.utils.autoreload:D:\Web app\babaco\shop\views.py changed, reloading.
DEBUG:asyncio:Using proactor: IocpProactor
INFO:django.utils.autoreload:D:\Web app\babaco\user\views.py changed, reloading.
DEBUG:asyncio:Using proactor: IocpProactor
INFO:django.utils.autoreload:D:\Web app\babaco\store\urls.py changed, reloading.
DEBUG:asyncio:Using proactor: IocpProactor
INFO:django.utils.autoreload:D:\Web app\babaco\shop\views.py changed, reloading.
DEBUG:asyncio:Using proactor: IocpProactor
INFO:django.utils.autoreload:D:\Web app\babaco\user\views.py changed, reloading.
DEBUG:asyncio:Using proactor: IocpProactor
INFO:django.utils.autoreload:D:\Web app\babaco\store\urls.py changed, reloading.
DEBUG:asyncio:Using proactor: IocpProactor
INFO:django.utils.autoreload:D:\Web app\babaco\store\views.py changed, reloading.
DEBUG:asyncio:Using proactor: IocpProactor
INFO:django.utils.autoreload:D:\Web app\babaco\user\views.py changed, reloading.
DEBUG:asyncio:Using proactor: IocpProactor
INFO:django.utils.autoreload:D:\Web app\babaco\shop\views.py changed, reloading.
DEBUG:asyncio:Using proactor: IocpProactor
INFO:django.utils.autoreload:D:\Web app\babaco\store\views.py changed, reloading.
DEBUG:asyncio:Using proactor: IocpProactor
INFO:django.utils.autoreload:D:\Web app\babaco\store\views.py changed, reloading.
DEBUG:asyncio:Using proactor: IocpProactor
WARNING:django.request:Not Found: /signup
ERROR:django.request:Internal Server Error: /store/login/
Traceback (most recent call last):
  File "D:\Web app\django\lib\site-packages\django\core\handlers\exception.py", line 47, in inner
    response = get_response(request)
  File "D:\Web app\django\lib\site-packages\django\core\handlers\base.py", line 179, in _get_response
    response = wrapped_callback(request, *callback_args, **callback_kwargs)
  File "D:\Web app\babaco\store\views.py", line 14, in store_login_view
    return login_view(req, user='store', database=Store, ret='home.store')
  File "D:\Web app\babaco\shop\views.py", line 59, in login_view
    return redirect('ret')
  File "D:\Web app\django\lib\site-packages\django\shortcuts.py", line 41, in redirect
    return redirect_class(resolve_url(to, *args, **kwargs))
  File "D:\Web app\django\lib\site-packages\django\shortcuts.py", line 131, in resolve_url
    return reverse(to, args=args, kwargs=kwargs)
  File "D:\Web app\django\lib\site-packages\django\urls\base.py", line 87, in reverse
    return iri_to_uri(resolver._reverse_with_prefix(view, prefix, *args, **kwargs))
  File "D:\Web app\django\lib\site-packages\django\urls\resolvers.py", line 685, in _reverse_with_prefix
    raise NoReverseMatch(msg)
django.urls.exceptions.NoReverseMatch: Reverse for 'ret' not found. 'ret' is not a valid view function or pattern name.
INFO:django.utils.autoreload:D:\Web app\babaco\shop\views.py changed, reloading.
DEBUG:asyncio:Using proactor: IocpProactor
INFO:django.utils.autoreload:D:\Web app\babaco\store\views.py changed, reloading.
DEBUG:asyncio:Using proactor: IocpProactor
INFO:django.utils.autoreload:D:\Web app\babaco\shop\views.py changed, reloading.
DEBUG:asyncio:Using proactor: IocpProactor
INFO:django.utils.autoreload:D:\Web app\babaco\shop\views.py changed, reloading.
DEBUG:asyncio:Using proactor: IocpProactor
INFO:django.utils.autoreload:D:\Web app\babaco\store\views.py changed, reloading.
DEBUG:asyncio:Using proactor: IocpProactor
INFO:django.utils.autoreload:D:\Web app\babaco\store\views.py changed, reloading.
DEBUG:asyncio:Using proactor: IocpProactor
WARNING:django.request:Not Found: /store/re
